<?xml version="1.0"?>
<robot name="/Users/correll/Downloads/pybullet-planning/models/tiago/tiagolite.urdf" xmlns:xacro="http://ros.org/wiki/xacro">
  <link name="world_link"/>
  <link name="base_link_0"/>
  <link name="base_link_1"/>
  <joint name="x" type="prismatic">
    <limit lower="-5" upper="5"/>
    <parent link="world_link"/>
    <child link="base_link_0"/>
    <axis xyz="1 0 0"/>
  </joint>
  <joint name="y" type="prismatic">
    <limit lower="-5" upper="5"/>
    <parent link="base_link_0"/>
    <child link="base_link_1"/>
    <axis xyz="0 1 0"/>
  </joint>
  <joint name="theta" type="continuous">
    <parent link="base_link_1"/>
    <child link="base_link"/>
    <axis xyz="0 0 1"/>
  </joint>
  <link name="base_link">
    <visual>
      <origin xyz="0 0 0.06" rpy="0 0 0"/>
      <geometry>
        <cylinder radius="0.265" length="0.276"/>
      </geometry>
    </visual>
    <collision>
      <origin xyz="0 0 0.06" rpy="0 0 0"/>
      <geometry>
        <cylinder radius="0.265" length="0.276"/>
      </geometry>
    </collision>
    <visual>
      <origin xyz="-0.201 0.1062 0.28" rpy="0 0 0"/>
      <geometry>
        <cylinder radius="0.007" length="0.173"/>
      </geometry>
    </visual>
    <collision>
      <origin xyz="-0.201 0.1062 0.28" rpy="0 0 0"/>
      <geometry>
        <cylinder radius="0.007" length="0.173"/>
      </geometry>
    </collision>
    <visual>
      <origin xyz="-0.201 -0.1062 0.28" rpy="0 0 0"/>
      <geometry>
        <cylinder radius="0.007" length="0.173"/>
      </geometry>
    </visual>
    <collision>
      <origin xyz="-0.201 -0.1062 0.28" rpy="0 0 0"/>
      <geometry>
        <cylinder radius="0.007" length="0.173"/>
      </geometry>
    </collision>
  </link>
  <joint name="CASTER_WHEEL_BACK_LEFT_JOINT" type="continuous">
    <parent link="base_link"/>
    <child link="caster_back_left_1_link"/>
    <axis xyz="0 0 1"/>
    <origin xyz="-0.1735 0.102 -0.0335" rpy="0 0 0"/>
  </joint>
  <link name="caster_back_left_1_link">
    <visual>
      <origin xyz="-0.003 0 -0.022" rpy="0 0 0"/>
      <geometry>
        <box size="0.036 0.032 0.04"/>
      </geometry>
    </visual>
    <collision>
      <origin xyz="-0.003 0 -0.022" rpy="0 0 0"/>
      <geometry>
        <box size="0.036 0.032 0.04"/>
      </geometry>
    </collision>
  </link>
  <joint name="SMALL_WHEEL_JOINT" type="continuous">
    <parent link="caster_back_left_1_link"/>
    <child link="caster_back_left_2_link"/>
    <axis xyz="0 -0.000004 1"/>
    <origin xyz="-0.016 0 -0.04" rpy="-1.5708 0 0"/>
  </joint>
  <link name="caster_back_left_2_link">
    <visual>
      <origin xyz="0 0 0" rpy="0 0 0"/>
      <geometry>
        <cylinder radius="0.025" length="0.015"/>
      </geometry>
    </visual>
    <collision>
      <origin xyz="0 0 0" rpy="0 0 0"/>
      <geometry>
        <cylinder radius="0.025" length="0.015"/>
      </geometry>
    </collision>
  </link>
  <joint name="CASTER_WHEEL_BACK_RIGHT_JOINT" type="continuous">
    <parent link="base_link"/>
    <child link="caster_back_right_1_link"/>
    <axis xyz="0 0 1"/>
    <origin xyz="-0.1735 -0.102 -0.0335" rpy="0 0 0"/>
  </joint>
  <link name="caster_back_right_1_link">
    <visual>
      <origin xyz="-0.003 0 -0.022" rpy="0 0 0"/>
      <geometry>
        <box size="0.036 0.032 0.04"/>
      </geometry>
    </visual>
    <collision>
      <origin xyz="-0.003 0 -0.022" rpy="0 0 0"/>
      <geometry>
        <box size="0.036 0.032 0.04"/>
      </geometry>
    </collision>
  </link>
  <joint name="SMALL_WHEEL_JOINT_0" type="continuous">
    <parent link="caster_back_right_1_link"/>
    <child link="caster_back_right_2_link"/>
    <axis xyz="0 -0.000004 1"/>
    <origin xyz="-0.016 0 -0.04" rpy="-1.5708 0 0"/>
  </joint>
  <link name="caster_back_right_2_link">
    <visual>
      <origin xyz="0 0 0" rpy="0 0 0"/>
      <geometry>
        <cylinder radius="0.025" length="0.015"/>
      </geometry>
    </visual>
    <collision>
      <origin xyz="0 0 0" rpy="0 0 0"/>
      <geometry>
        <cylinder radius="0.025" length="0.015"/>
      </geometry>
    </collision>
  </link>
  <joint name="CASTER_WHEEL_FRONT_LEFT_JOINT" type="continuous">
    <parent link="base_link"/>
    <child link="caster_front_left_1_link"/>
    <axis xyz="0 0 1"/>
    <origin xyz="0.1695 0.102 -0.0335" rpy="0 0 0"/>
  </joint>
  <link name="caster_front_left_1_link">
    <visual>
      <origin xyz="-0.003 0 -0.022" rpy="0 0 0"/>
      <geometry>
        <box size="0.036 0.032 0.04"/>
      </geometry>
    </visual>
    <collision>
      <origin xyz="-0.003 0 -0.022" rpy="0 0 0"/>
      <geometry>
        <box size="0.036 0.032 0.04"/>
      </geometry>
    </collision>
  </link>
  <joint name="SMALL_WHEEL_JOINT_1" type="continuous">
    <parent link="caster_front_left_1_link"/>
    <child link="caster_front_left_2_link"/>
    <axis xyz="0 -0.000004 1"/>
    <origin xyz="-0.016 0 -0.04" rpy="-1.5708 0 0"/>
  </joint>
  <link name="caster_front_left_2_link">
    <visual>
      <origin xyz="0 0 0" rpy="0 0 0"/>
      <geometry>
        <cylinder radius="0.025" length="0.015"/>
      </geometry>
    </visual>
    <collision>
      <origin xyz="0 0 0" rpy="0 0 0"/>
      <geometry>
        <cylinder radius="0.025" length="0.015"/>
      </geometry>
    </collision>
  </link>
  <joint name="CASTER_WHEEL_FRONT_RIGHT_JOINT" type="continuous">
    <parent link="base_link"/>
    <child link="caster_front_right_1_link"/>
    <axis xyz="0 0 1"/>
    <origin xyz="0.1695 -0.102 -0.0335" rpy="0 0 0"/>
  </joint>
  <link name="caster_front_right_1_link">
    <visual>
      <origin xyz="-0.003 0 -0.022" rpy="0 0 0"/>
      <geometry>
        <box size="0.036 0.032 0.04"/>
      </geometry>
    </visual>
    <collision>
      <origin xyz="-0.003 0 -0.022" rpy="0 0 0"/>
      <geometry>
        <box size="0.036 0.032 0.04"/>
      </geometry>
    </collision>
  </link>
  <joint name="SMALL_WHEEL_JOINT_2" type="continuous">
    <parent link="caster_front_right_1_link"/>
    <child link="caster_front_right_2_link"/>
    <axis xyz="0 -0.000004 1"/>
    <origin xyz="-0.016 0 -0.04" rpy="-1.5708 0 0"/>
  </joint>
  <link name="caster_front_right_2_link">
    <visual>
      <origin xyz="0 0 0" rpy="0 0 0"/>
      <geometry>
        <cylinder radius="0.025" length="0.015"/>
      </geometry>
    </visual>
    <collision>
      <origin xyz="0 0 0" rpy="0 0 0"/>
      <geometry>
        <cylinder radius="0.025" length="0.015"/>
      </geometry>
    </collision>
  </link>
  <joint name="wheel_left_joint" type="continuous">
    <parent link="base_link"/>
    <child link="wheel_left_link"/>
    <axis xyz="0 -0.000004 -1"/>
    <limit effort="10" velocity="10.1523"/>
    <origin xyz="0 0.2022 0" rpy="1.5708 0 0"/>
  </joint>
  <link name="wheel_left_link">
    <visual>
      <origin xyz="0 0 0.0002" rpy="0 0 0"/>
      <geometry>
        <cylinder radius="0.0985" length="0.04"/>
      </geometry>
    </visual>
    <collision>
      <origin xyz="0 0 0.0002" rpy="0 0 0"/>
      <geometry>
        <cylinder radius="0.0985" length="0.04"/>
      </geometry>
    </collision>
  </link>
  <joint name="wheel_right_joint" type="continuous">
    <parent link="base_link"/>
    <child link="wheel_right_link"/>
    <axis xyz="0 -0.000004 -1"/>
    <limit effort="10" velocity="10.1523"/>
    <origin xyz="0 -0.2022 0.0002" rpy="1.5708 0 0"/>
  </joint>
  <link name="wheel_right_link">
    <visual>
      <origin xyz="0 0 -0.0002" rpy="0 0 0"/>
      <geometry>
        <cylinder radius="0.0985" length="0.04"/>
      </geometry>
    </visual>
    <collision>
      <origin xyz="0 0 -0.0002" rpy="0 0 0"/>
      <geometry>
        <cylinder radius="0.0985" length="0.04"/>
      </geometry>
    </collision>
  </link>
  <link name="base_sonar_01_link">
  </link>
  <joint name="base_link_base_sonar_01_link_joint" type="fixed">
    <parent link="base_link"/>
    <child link="base_sonar_01_link"/>
    <origin xyz="-0.183 -0.183 0.1728" rpy="0 0 -2.356185"/>
  </joint>
  <link name="base_sonar_02_link">
  </link>
  <joint name="base_link_base_sonar_02_link_joint" type="fixed">
    <parent link="base_link"/>
    <child link="base_sonar_02_link"/>
    <origin xyz="-0.259 0 0.173" rpy="0 0 -3.141585"/>
  </joint>
  <link name="base_sonar_03_link">
  </link>
  <joint name="base_link_base_sonar_03_link_joint" type="fixed">
    <parent link="base_link"/>
    <child link="base_sonar_03_link"/>
    <origin xyz="-0.183 0.183 0.173" rpy="0 0 2.3562"/>
  </joint>
  <link name="base_cover_link">
    <visual>
      <origin xyz="0 0 0.043" rpy="0 0 0"/>
      <geometry>
        <cylinder radius="0.272" length="0.086"/>
      </geometry>
    </visual>
    <collision>
      <origin xyz="0 0 0.043" rpy="0 0 0"/>
      <geometry>
        <cylinder radius="0.272" length="0.086"/>
      </geometry>
    </collision>
  </link>
  <joint name="base_link_base_cover_link_joint" type="fixed">
    <parent link="base_link"/>
    <child link="base_cover_link"/>
    <origin xyz="0 0 0.03" rpy="0 0 0"/>
  </joint>
  <link name="base_footprint">
  </link>
  <joint name="base_link_base_footprint_joint" type="fixed">
    <parent link="base_link"/>
    <child link="base_footprint"/>
    <origin xyz="0 0 -0.095" rpy="0 0 0"/>
  </joint>
  <link name="gyro">
  </link>
  <joint name="base_link_gyro_joint" type="fixed">
    <parent link="base_link"/>
    <child link="gyro"/>
    <origin xyz="0 0 0" rpy="0 0 0"/>
  </joint>
  <link name="inertial unit">
  </link>
  <joint name="base_link_inertial unit_joint" type="fixed">
    <parent link="base_link"/>
    <child link="inertial unit"/>
    <origin xyz="0 0 0" rpy="0 0 0"/>
  </joint>
  <link name="accelerometer">
  </link>
  <joint name="base_link_accelerometer_joint" type="fixed">
    <parent link="base_link"/>
    <child link="accelerometer"/>
    <origin xyz="0 0 0" rpy="0 0 0"/>
  </joint>
  <link name="Hokuyo URG-04LX-UG01">
    <visual>
      <origin xyz="0 0 -0.018" rpy="1.570741 0.000118 -1.570741"/>
      <geometry>
        <box size="0.05 0.07 0.05"/>
      </geometry>
    </visual>
    <collision>
      <origin xyz="0 0 -0.018" rpy="1.570741 0.000118 -1.570741"/>
      <geometry>
        <box size="0.05 0.07 0.05"/>
      </geometry>
    </collision>
  </link>
  <joint name="base_link_Hokuyo URG-04LX-UG01_joint" type="fixed">
    <parent link="base_link"/>
    <child link="Hokuyo URG-04LX-UG01"/>
    <origin xyz="0.202 0 -0.004" rpy="0 0 0"/>
  </joint>
  <link name="Torso">
    <visual>
      <origin xyz="0 0 0.275" rpy="0 0 0"/>
      <geometry>
        <box size="0.18 0.2 0.55"/>
      </geometry>
    </visual>
    <collision>
      <origin xyz="0 0 0.275" rpy="0 0 0"/>
      <geometry>
        <box size="0.18 0.2 0.55"/>
      </geometry>
    </collision>
    <visual>
      <origin xyz="0.085 0 0.02" rpy="0 0 0"/>
      <geometry>
        <box size="0.4 0.254 0.04"/>
      </geometry>
    </visual>
    <collision>
      <origin xyz="0.085 0 0.02" rpy="0 0 0"/>
      <geometry>
        <box size="0.4 0.254 0.04"/>
      </geometry>
    </collision>
    <visual>
      <origin xyz="0.001 0 0.05" rpy="0 0 0"/>
      <geometry>
        <box size="0.233 0.26 0.12"/>
      </geometry>
    </visual>
    <collision>
      <origin xyz="0.001 0 0.05" rpy="0 0 0"/>
      <geometry>
        <box size="0.233 0.26 0.12"/>
      </geometry>
    </collision>
  </link>
  <joint name="base_link_Torso_joint" type="fixed">
    <parent link="base_link"/>
    <child link="Torso"/>
    <origin xyz="-0.054 0 0.193" rpy="0 0 0"/>
  </joint>
  <joint name="torso_lift_joint" type="prismatic">
    <parent link="Torso"/>
    <child link="torso_lift_link"/>
    <axis xyz="0 0 1"/>
    <origin xyz="0 0 0.6" rpy="0 0 0"/>
    <limit effort="2000" lower="0" upper="0.35" velocity="0.07"/>
  </joint>
  <link name="torso_lift_link">
    <visual>
      <origin xyz="0.164 0 -0.032" rpy="0 0 0"/>
      <geometry>
        <box size="0.15 0.138 0.074"/>
      </geometry>
    </visual>
    <collision>
      <origin xyz="0.164 0 -0.032" rpy="0 0 0"/>
      <geometry>
        <box size="0.15 0.138 0.074"/>
      </geometry>
    </collision>
    <visual>
      <origin xyz="0.1389 0 -0.0432" rpy="0 -0.43 0"/>
      <geometry>
        <box size="0.12 0.134 0.097"/>
      </geometry>
    </visual>
    <collision>
      <origin xyz="0.1389 0 -0.0432" rpy="0 -0.43 0"/>
      <geometry>
        <box size="0.12 0.134 0.097"/>
      </geometry>
    </collision>
    <visual>
      <origin xyz="-0.016 0 -0.05" rpy="0 0 0"/>
      <geometry>
        <box size="0.291 0.333 0.11"/>
      </geometry>
    </visual>
    <collision>
      <origin xyz="-0.016 0 -0.05" rpy="0 0 0"/>
      <geometry>
        <box size="0.291 0.333 0.11"/>
      </geometry>
    </collision>
    <visual>
      <origin xyz="0.003 0 -0.283" rpy="0 0 0"/>
      <geometry>
        <box size="0.228 0.263 0.358"/>
      </geometry>
    </visual>
    <collision>
      <origin xyz="0.003 0 -0.283" rpy="0 0 0"/>
      <geometry>
        <box size="0.228 0.263 0.358"/>
      </geometry>
    </collision>
  </link>
  <joint name="head_1_joint" type="revolute">
    <parent link="torso_lift_link"/>
    <child link="head_1_link"/>
    <axis xyz="0 0 1"/>
    <limit effort="5.197" lower="-1.24" upper="1.24" velocity="3"/>
    <origin xyz="0.182 0 0" rpy="0 0 0"/>
  </joint>
  <link name="head_1_link">
    <visual>
      <origin xyz="0.01 0 0.097" rpy="-1.5708 0 0"/>
      <geometry>
        <cylinder radius="0.082" length="0.09"/>
      </geometry>
    </visual>
    <collision>
      <origin xyz="0.01 0 0.097" rpy="-1.5708 0 0"/>
      <geometry>
        <cylinder radius="0.082" length="0.09"/>
      </geometry>
    </collision>
    <visual>
      <origin xyz="-0.005 0 0.005" rpy="0 0 0"/>
      <geometry>
        <box size="0.103 0.088 0.103"/>
      </geometry>
    </visual>
    <collision>
      <origin xyz="-0.005 0 0.005" rpy="0 0 0"/>
      <geometry>
        <box size="0.103 0.088 0.103"/>
      </geometry>
    </collision>
  </link>
  <joint name="head_2_joint" type="revolute">
    <parent link="head_1_link"/>
    <child link="head_2_link"/>
    <axis xyz="0 0.000004 1"/>
    <limit effort="2.77" lower="-0.98" upper="0.79" velocity="3"/>
    <origin xyz="0.005 0 0.098" rpy="1.5708 0 0"/>
  </joint>
  <link name="head_2_link">
    <visual>
      <origin xyz="-0.009 0.0466 0" rpy="0 0 -0.7"/>
      <geometry>
        <box size="0.092 0.132 0.26"/>
      </geometry>
    </visual>
    <collision>
      <origin xyz="-0.009 0.0466 0" rpy="0 0 -0.7"/>
      <geometry>
        <box size="0.092 0.132 0.26"/>
      </geometry>
    </collision>
    <visual>
      <origin xyz="0.008 -0.019 0" rpy="0 0 -1.5708"/>
      <geometry>
        <cylinder radius="0.03" length="0.132"/>
      </geometry>
    </visual>
    <collision>
      <origin xyz="0.008 -0.019 0" rpy="0 0 -1.5708"/>
      <geometry>
        <cylinder radius="0.03" length="0.132"/>
      </geometry>
    </collision>
    <visual>
      <origin xyz="0.054 0.06 0" rpy="0 0 0"/>
      <geometry>
        <box size="0.111 0.13 0.16"/>
      </geometry>
    </visual>
    <collision>
      <origin xyz="0.054 0.06 0" rpy="0 0 0"/>
      <geometry>
        <box size="0.111 0.13 0.16"/>
      </geometry>
    </collision>
    <visual>
      <origin xyz="0.053 0.056 -0.068" rpy="3.141593 -1.570793 3.141593"/>
      <geometry>
        <cylinder radius="0.0667" length="0.111"/>
      </geometry>
    </visual>
    <collision>
      <origin xyz="0.053 0.056 -0.068" rpy="3.141593 -1.570793 3.141593"/>
      <geometry>
        <cylinder radius="0.0667" length="0.111"/>
      </geometry>
    </collision>
    <visual>
      <origin xyz="0.053 0.056 0.068" rpy="3.141593 -1.570793 3.141593"/>
      <geometry>
        <cylinder radius="0.0667" length="0.111"/>
      </geometry>
    </visual>
    <collision>
      <origin xyz="0.053 0.056 0.068" rpy="3.141593 -1.570793 3.141593"/>
      <geometry>
        <cylinder radius="0.0667" length="0.111"/>
      </geometry>
    </collision>
  </link>
  <link name="Astra">
    <visual>
      <origin xyz="0.006 0 0.034" rpy="0 0 0"/>
      <geometry>
        <box size="0.04 0.165 0.029"/>
      </geometry>
    </visual>
    <collision>
      <origin xyz="0.006 0 0.034" rpy="0 0 0"/>
      <geometry>
        <box size="0.04 0.165 0.029"/>
      </geometry>
    </collision>
    <visual>
      <origin xyz="-0.009 0 0.007" rpy="0 0 0"/>
      <geometry>
        <box size="0.061 0.06 0.014"/>
      </geometry>
    </visual>
    <collision>
      <origin xyz="-0.009 0 0.007" rpy="0 0 0"/>
      <geometry>
        <box size="0.061 0.06 0.014"/>
      </geometry>
    </collision>
  </link>
  <joint name="head_2_link_Astra_joint" type="fixed">
    <parent link="head_2_link"/>
    <child link="Astra"/>
    <origin xyz="0.079 0.0452 -0.009" rpy="-1.5708 0 0"/>
  </joint>
  <link name="Astra depth">
  </link>
  <joint name="Astra_Astra depth_joint" type="fixed">
    <parent link="Astra"/>
    <child link="Astra depth"/>
    <origin xyz="0.027 0.037 0.034" rpy="0 0 0"/>
  </joint>
  <link name="Astra rgb">
  </link>
  <joint name="Astra_Astra rgb_joint" type="fixed">
    <parent link="Astra"/>
    <child link="Astra rgb"/>
    <origin xyz="0.027 0.011 0.034" rpy="-1.570796 0 -1.570796"/>
  </joint>
  <link name="gps">
  </link>
  <joint name="base_link_gps_joint" type="fixed">
    <parent link="base_link"/>
    <child link="gps"/>
    <origin xyz="0 0 0" rpy="0 0 0"/>
  </joint>
  <link name="compass">
  </link>
  <joint name="base_link_compass_joint" type="fixed">
    <parent link="base_link"/>
    <child link="compass"/>
    <origin xyz="0 0 0" rpy="0 0 0"/>
  </joint>
  <link name="display">
  </link>
  <joint name="base_link_display_joint" type="fixed">
    <parent link="base_link"/>
    <child link="display"/>
    <origin xyz="0 0 0" rpy="0 0 0"/>
  </joint>
</robot>
