<?xml version="1.0" ?>
<!-- =================================================================================== -->
<!-- |    This document was autogenerated by xacro from kr6_r900_mit_suction_gripper.xacro | -->
<!-- |    EDITING THIS FILE BY HAND IS NOT RECOMMENDED                                 | -->
<!-- =================================================================================== -->
<robot name="kr6_r900_mit_suction_gripper" xmlns:xacro="http://wiki.ros.org/xacro">
  <!-- colours based on RAL values given in "FAQ - Colours of robot and robot
       controller", version "KUKA.Tifs | 2010-01-21 |YM| DefaultColorsRobotAndController.doc",
       downloaded 2015-07-18 from
       http://www.kuka.be/main/cservice/faqs/hardware/DefaultColorsRobotAndController.pdf

       all RAL colours converted using http://www.visual-graphics.de/en/customer-care/ral-colours
  -->
  <link name="robot_base_link">
    <visual>
      <origin rpy="0 0 0" xyz="0 0 0"/>
      <geometry>
        <mesh filename="package://kuka_kr6_support/meshes/kr6_agilus/visual/base_link.dae"/>
      </geometry>
      <material name="">
        <color rgba="0.505882352941 0.470588235294 0.388235294118 1.0"/>
      </material>
    </visual>
    <collision>
      <origin rpy="0 0 0" xyz="0 0 0"/>
      <geometry>
        <mesh filename="package://kuka_kr6_support/meshes/kr6_agilus/collision/base_link.stl"/>
      </geometry>
    </collision>
  </link>
  <link name="robot_link_1">
    <visual>
      <origin rpy="0 0 0" xyz="0 0 0"/>
      <geometry>
        <mesh filename="package://kuka_kr6_support/meshes/kr6_agilus/visual/link_1.dae"/>
      </geometry>
      <material name="">
        <color rgba="0.964705882353 0.470588235294 0.156862745098 1.0"/>
      </material>
    </visual>
    <collision>
      <origin rpy="0 0 0" xyz="0 0 0"/>
      <geometry>
        <mesh filename="package://kuka_kr6_support/meshes/kr6_agilus/collision/link_1.stl"/>
      </geometry>
    </collision>
  </link>
  <link name="robot_link_2">
    <visual>
      <origin rpy="0 0 0" xyz="0 0 0"/>
      <geometry>
        <mesh filename="package://kuka_kr6_support/meshes/kr6r900sixx/visual/link_2.dae"/>
      </geometry>
      <material name="">
        <color rgba="0.964705882353 0.470588235294 0.156862745098 1.0"/>
      </material>
    </visual>
    <collision>
      <origin rpy="0 0 0" xyz="0 0 0"/>
      <geometry>
        <mesh filename="package://kuka_kr6_support/meshes/kr6r900sixx/collision/link_2.stl"/>
      </geometry>
    </collision>
  </link>
  <link name="robot_link_3">
    <visual>
      <origin rpy="0 0 0" xyz="0 0 0"/>
      <geometry>
        <mesh filename="package://kuka_kr6_support/meshes/kr6_agilus/visual/link_3.dae"/>
      </geometry>
      <material name="">
        <color rgba="0.964705882353 0.470588235294 0.156862745098 1.0"/>
      </material>
    </visual>
    <collision>
      <origin rpy="0 0 0" xyz="0 0 0"/>
      <geometry>
        <mesh filename="package://kuka_kr6_support/meshes/kr6_agilus/collision/link_3.stl"/>
      </geometry>
    </collision>
  </link>
  <link name="robot_link_4">
    <visual>
      <origin rpy="0 0 0" xyz="0 0 0"/>
      <geometry>
        <mesh filename="package://kuka_kr6_support/meshes/kr6r900sixx/visual/link_4.dae"/>
      </geometry>
      <material name="">
        <color rgba="0.964705882353 0.470588235294 0.156862745098 1.0"/>
      </material>
    </visual>
    <collision>
      <origin rpy="0 0 0" xyz="0 0 0"/>
      <geometry>
        <mesh filename="package://kuka_kr6_support/meshes/kr6r900sixx/collision/link_4.stl"/>
      </geometry>
    </collision>
  </link>
  <link name="robot_link_5">
    <visual>
      <origin rpy="0 0 0" xyz="0 0 0"/>
      <geometry>
        <mesh filename="package://kuka_kr6_support/meshes/kr6_agilus/visual/link_5.dae"/>
      </geometry>
      <material name="">
        <color rgba="0.964705882353 0.470588235294 0.156862745098 1.0"/>
      </material>
    </visual>
    <collision>
      <origin rpy="0 0 0" xyz="0 0 0"/>
      <geometry>
        <mesh filename="package://kuka_kr6_support/meshes/kr6_agilus/collision/link_5.stl"/>
      </geometry>
    </collision>
  </link>
  <link name="robot_link_6">
    <visual>
      <origin rpy="0 0 0" xyz="0 0 0"/>
      <geometry>
        <mesh filename="package://kuka_kr6_support/meshes/kr6_agilus/visual/link_6.dae"/>
      </geometry>
      <material name="">
        <color rgba="0.505882352941 0.470588235294 0.388235294118 1.0"/>
      </material>
    </visual>
    <collision>
      <origin rpy="0 0 0" xyz="0 0 0"/>
      <geometry>
        <mesh filename="package://kuka_kr6_support/meshes/kr6_agilus/collision/link_6.stl"/>
      </geometry>
    </collision>
  </link>
  <!-- This frame corresponds to the $FLANGE coordinate system in KUKA KRC controllers. -->
  <link name="robot_tool0"/>
  <joint name="robot_joint_a1" type="revolute">
    <origin rpy="0 0 0" xyz="0 0 0.400"/>
    <parent link="robot_base_link"/>
    <child link="robot_link_1"/>
    <axis xyz="0 0 -1"/>
    <limit effort="0" lower="-2.96705972839" upper="2.96705972839" velocity="6.28318530718"/>
  </joint>
  <joint name="robot_joint_a2" type="revolute">
    <origin rpy="0 0 0" xyz="0.025 0 0"/>
    <parent link="robot_link_1"/>
    <child link="robot_link_2"/>
    <axis xyz="0 1 0"/>
    <limit effort="0" lower="-3.31612557879" upper="0.785398163397" velocity="5.23598775598"/>
  </joint>
  <joint name="robot_joint_a3" type="revolute">
    <origin rpy="0 0 0" xyz="0.455 0 0"/>
    <parent link="robot_link_2"/>
    <child link="robot_link_3"/>
    <axis xyz="0 1 0"/>
    <limit effort="0" lower="-2.09439510239" upper="2.72271363311" velocity="6.28318530718"/>
  </joint>
  <joint name="robot_joint_a4" type="revolute">
    <origin rpy="0 0 0" xyz="0 0 0.035"/>
    <parent link="robot_link_3"/>
    <child link="robot_link_4"/>
    <axis xyz="-1 0 0"/>
    <limit effort="0" lower="-3.22885911619" upper="3.22885911619" velocity="6.6497044501"/>
  </joint>
  <joint name="robot_joint_a5" type="revolute">
    <origin rpy="0 0 0" xyz="0.420 0 0"/>
    <parent link="robot_link_4"/>
    <child link="robot_link_5"/>
    <axis xyz="0 1 0"/>
    <limit effort="0" lower="-2.09439510239" upper="2.09439510239" velocity="6.77187749774"/>
  </joint>
  <joint name="robot_joint_a6" type="revolute">
    <origin rpy="0 0 0" xyz="0.080 0 0"/>
    <parent link="robot_link_5"/>
    <child link="robot_link_6"/>
    <axis xyz="-1 0 0"/>
    <limit effort="0" lower="-6.10865238198" upper="6.10865238198" velocity="10.7337748998"/>
  </joint>
  <joint name="robot_joint_a6-tool0" type="fixed">
    <parent link="robot_link_6"/>
    <child link="robot_tool0"/>
    <origin rpy="0 1.57079632679 0" xyz="0 0 0"/>
  </joint>
  <!-- ROS base_link to KUKA $ROBROOT coordinate system transform -->
  <link name="robot_base"/>
  <joint name="robot_base_link-base" type="fixed">
    <origin rpy="0 0 0" xyz="0 0 0"/>
    <parent link="robot_base_link"/>
    <child link="robot_base"/>
  </joint>
  <!-- link list -->
  <link name="eef_base_link">
    <visual>
      <origin rpy="0 0 0" xyz="8.8e-05 0.000769 -0.002121"/>
      <geometry>
        <mesh filename="package://mit_arch_suction_gripper/meshes/visual/suction-gripper_mit-arch_visual.stl" scale=".001 .001 .001"/>
      </geometry>
      <material name="grey">
        <color rgba="0.5 0.5 0.5 1.0"/>
      </material>
    </visual>
    <collision>
      <origin rpy="0 0 0" xyz="8.8e-05 0.000769 -0.002121"/>
      <geometry>
        <mesh filename="package://mit_arch_suction_gripper/meshes/collision/suction-gripper_mit-arch_collision.stl" scale=".001 .001 .001"/>
      </geometry>
      <material name="red">
        <color rgba="1 0 0 1"/>
      </material>
    </collision>
  </link>
  <link name="eef_tcp_frame"/>
  <!-- end of link list -->
  <!-- joint list -->
  <joint name="eef_base_to_tcp" type="fixed">
    <origin rpy="0.0 1.57079632679 0.0" xyz="0.145336 0.001949 0.096286"/>
    <parent link="eef_base_link"/>
    <child link="eef_tcp_frame"/>
  </joint>
  <!-- end of joint list -->
  <link name="workspace_base_link"/>
  <!--link name="workspace_objects">
    <visual>
      <geometry>
        <mesh filename="package://framefab_kr6_r900_support/meshes/visual/MIT_3-412_workspace_full.stl"/>
      </geometry>
      <material name="grey">
        <color rgba="0.5 0.5 0.5 1.0"/>
      </material>
    </visual>
    <collision>
      <geometry>
        <mesh filename="package://framefab_kr6_r900_support/meshes/collision/MIT_3-412_workspace_simplified.stl"/>
      </geometry>
    </collision>
  </link>
  <joint name="workspace_baselink_to_objects" type="fixed">
    <parent link="workspace_base_link"/>
    <child link="workspace_objects"/>
    <origin rpy="0 0 0" xyz="0 0 0"/>
  </joint-->
  <link name="base_link"/>
  <!-- Attach the end effector to the end of the robot arm (tool0) -->
  <joint name="ee_to_robot" type="fixed">
    <parent link="robot_tool0"/>
    <child link="eef_base_link"/>
    <origin rpy="0 0 0" xyz="0 0 0"/>
  </joint>
  <!-- start of arm-workcell joint definitions -->
  <joint name="world_to_base" type="fixed">
    <parent link="base_link"/>
    <child link="robot_base_link"/>
    <origin rpy="0 0 0" xyz="0 0 0"/>
  </joint>
  <joint name="world_to_workspace" type="fixed">
    <parent link="base_link"/>
    <child link="workspace_base_link"/>
    <origin rpy="0 0 0" xyz="0 0 0"/>
  </joint>
</robot>
