<?xml version="1.0" ?>
<!-- =================================================================================== -->
<!-- |    This document was autogenerated by xacro from irb6600_with_linear_track_workspace.xacro | -->
<!-- |    EDITING THIS FILE BY HAND IS NOT RECOMMENDED                                 | -->
<!-- =================================================================================== -->
<robot name="abb_irb6600_track" xmlns:xacro="http://ros.org/wiki/xacro">
  <!-- link list -->
  <link name="robot_base_link">
    <collision name="collision">
      <geometry>
        <mesh filename="../meshes/irb6640/collision/base_link.stl"/>
      </geometry>
      <material name="yellow">
        <color rgba="0 1 1 1"/>
      </material>
    </collision>
    <visual name="visual">
      <geometry>
        <mesh filename="../meshes/irb6640/visual/base_link.stl"/>
      </geometry>
      <material name="orange">
        <color rgba="1 0.43 0 1"/>
      </material>
    </visual>
  </link>
  <link name="robot_link_1">
    <collision name="collision">
      <geometry>
        <mesh filename="../meshes/irb6640/collision/link_1.stl"/>
      </geometry>
      <material name="yellow"/>
    </collision>
    <visual name="visual">
      <geometry>
        <mesh filename="../meshes/irb6640/visual/link_1.stl"/>
      </geometry>
      <material name="orange"/>
    </visual>
  </link>
  <link name="robot_link_2">
    <collision name="collision">
      <geometry>
        <mesh filename="../meshes/irb6640/collision/link_2.stl"/>
      </geometry>
      <material name="yellow"/>
    </collision>
    <visual name="visual">
      <geometry>
        <mesh filename="../meshes/irb6640/visual/link_2.stl"/>
      </geometry>
      <material name="orange"/>
    </visual>
  </link>
  <link name="robot_link_3">
    <collision name="collision">
      <geometry>
        <mesh filename="../meshes/irb6640/collision/link_3.stl"/>
      </geometry>
      <material name="yellow"/>
    </collision>
    <visual name="visual">
      <geometry>
        <mesh filename="../meshes/irb6640/visual/link_3.stl"/>
      </geometry>
      <material name="orange"/>
    </visual>
  </link>
  <link name="robot_link_4">
    <collision name="collision">
      <geometry>
        <mesh filename="../meshes/irb6640/collision/link_4.stl"/>
      </geometry>
      <material name="yellow"/>
    </collision>
    <visual name="visual">
      <geometry>
        <mesh filename="../meshes/irb6640/visual/link_4.stl"/>
      </geometry>
      <material name="orange"/>
    </visual>
  </link>
  <link name="robot_link_5">
    <collision name="collision">
      <geometry>
        <mesh filename="../meshes/irb6640/collision/link_5.stl"/>
      </geometry>
      <material name="yellow"/>
    </collision>
    <visual name="visual">
      <geometry>
        <mesh filename="../meshes/irb6640/visual/link_5.stl"/>
      </geometry>
      <material name="orange"/>
    </visual>
  </link>
  <link name="robot_link_6">
    <collision name="collision">
      <geometry>
        <mesh filename="../meshes/irb6640/collision/link_6.stl"/>
      </geometry>
      <material name="yellow"/>
    </collision>
    <visual name="visual">
      <geometry>
        <mesh filename="../meshes/irb6640/visual/link_6.stl"/>
      </geometry>
      <material name="orange"/>
    </visual>
  </link>
  <link name="robot_tool0"/>
  <!--Cylinder and piston -->
  <link name="robot_link_cylinder">
    <collision name="collision">
      <geometry>
        <mesh filename="../meshes/irb6640/collision/cylinder.stl"/>
      </geometry>
      <material name="yellow"/>
    </collision>
    <visual name="visual">
      <geometry>
        <mesh filename="../meshes/irb6640/visual/cylinder.stl"/>
      </geometry>
      <material name="orange"/>
    </visual>
  </link>
  <link name="robot_link_piston">
    <collision name="collision">
      <geometry>
        <mesh filename="../meshes/irb6640/collision/piston.stl"/>
      </geometry>
      <material name="yellow"/>
    </collision>
    <visual name="visual">
      <geometry>
        <mesh filename="../meshes/irb6640/visual/piston.stl"/>
      </geometry>
      <material name="orange"/>
    </visual>
  </link>
  <!-- end of link list -->
  <!-- joint list -->
  <joint name="robot_joint_1" type="revolute">
    <origin rpy="0 0 0" xyz="0 0 0.227"/>
    <axis xyz="0 0 1"/>
    <parent link="robot_base_link"/>
    <child link="robot_link_1"/>
    <limit effort="0" lower="-2.967" upper="2.967" velocity="1.7453"/>
  </joint>
  <joint name="robot_joint_2" type="revolute">
    <origin rpy="0 0 0" xyz="0.322 0.03 0.551"/>
    <axis xyz="0 1 0"/>
    <parent link="robot_link_1"/>
    <child link="robot_link_2"/>
    <limit effort="0" lower="-1.134" upper="1.4855" velocity="1.5707"/>
  </joint>
  <joint name="robot_joint_3" type="revolute">
    <origin rpy="0 0 0" xyz="0 -0.2 1.07"/>
    <axis xyz="0 1 0"/>
    <parent link="robot_link_2"/>
    <child link="robot_link_3"/>
    <limit effort="0" lower="-3.142" upper="1.222" velocity="1.5707"/>
  </joint>
  <joint name="robot_joint_4" type="revolute">
    <origin rpy="0 0 0" xyz="-0.275 0.181 0.2"/>
    <axis xyz="1 0 0"/>
    <parent link="robot_link_3"/>
    <child link="robot_link_4"/>
    <limit effort="0" lower="-5.236" upper="5.236" velocity="2.9671"/>
  </joint>
  <joint name="robot_joint_5" type="revolute">
    <origin rpy="0 0 0" xyz="1.67 0 0 "/>
    <axis xyz="0 1 0"/>
    <parent link="robot_link_4"/>
    <child link="robot_link_5"/>
    <limit effort="0" lower="-2.094" upper="2.094" velocity="2.4435"/>
  </joint>
  <joint name="robot_joint_6" type="revolute">
    <origin rpy="0 0 0" xyz="0.153 0 0 "/>
    <axis xyz="1 0 0"/>
    <parent link="robot_link_5"/>
    <child link="robot_link_6"/>
    <limit effort="0" lower="-6.283" upper="6.283" velocity="3.3161"/>
  </joint>
  <joint name="robot_joint_6-tool0" type="fixed">
    <parent link="robot_link_6"/>
    <child link="robot_tool0"/>
    <origin rpy="0 1.57079632679 0" xyz=".055 0 0"/>
  </joint>
  <joint name="robot_joint_cylinder" type="fixed">
    <origin rpy="0 -0.170 0" xyz="-0.365 -0.1895 0.405"/>
    <axis xyz="0 1 0"/>
    <parent link="robot_link_1"/>
    <child link="robot_link_cylinder"/>
    <limit effort="0" lower="-2.96705973" upper="2.96705973" velocity="0"/>
  </joint>
  <joint name="robot_joint_piston" type="fixed">
    <origin rpy="0 0 0" xyz="0.475 0 0"/>
    <axis xyz="1 0 0"/>
    <parent link="robot_link_cylinder"/>
    <child link="robot_link_piston"/>
    <limit effort="0" lower="0" upper="0.6" velocity="0"/>
  </joint>
  <!-- end of joint list -->
  <!-- ROS base_link to ABB World Coordinates transform -->
  <link name="robot_base"/>
  <joint name="robot_base_link-base" type="fixed">
    <origin rpy="0 0 0" xyz="0 0 0"/>
    <parent link="robot_base_link"/>
    <child link="robot_base"/>
  </joint>

    <!--end effector-->
   <link name="eef_base_link">
     <visual>
       <origin rpy="0 0 0" xyz="0.0 0.0 0.0"/>
       <geometry>
         <mesh filename="../meshes/eth_rfl_gripper/visual/eth_rfl_gripper_visual.stl" scale=".001 .001 .001"/>
       </geometry>
       <material name="grey">
         <color rgba="0.5 0.5 0.5 1.0"/>
       </material>
     </visual>
     <collision>
       <origin rpy="0 0 0" xyz="0.0 0.0 0.0"/>
       <geometry>
         <mesh filename="../meshes/eth_rfl_gripper/collision/eth_rfl_gripper_collision.stl" scale=".001 .001 .001"/>
       </geometry>
       <material name="red">
         <color rgba="1 0 0 1"/>
       </material>
     </collision>
   </link>

  <joint name="eef_base_to_tcp" type="fixed">
    <origin rpy="0 0 0" xyz="0.0 0.0 0.475"/>
    <parent link="eef_base_link"/>
    <child link="eef_tcp_frame"/>
  </joint>

   <link name="eef_tcp_frame"/>

<!-- link list -->
  <!--<link name="eef_base_link">-->
    <!--<visual>-->
      <!--<origin rpy="0 0 0" xyz="8.8e-05 0.000769 -0.002121"/>-->
      <!--<geometry>-->
        <!--<mesh filename="package://asw_end_effector/meshes/visual/asw_hotend_end_effector.stl" scale=".001 .001 .001"/>-->
      <!--</geometry>-->
      <!--<material name="grey">-->
        <!--<color rgba="0.5 0.5 0.5 1.0"/>-->
      <!--</material>-->
    <!--</visual>-->
    <!--<collision>-->
      <!--<origin rpy="0 0 0" xyz="8.8e-05 0.000769 -0.002121"/>-->
      <!--<geometry>-->
        <!--<mesh filename="package://asw_end_effector/meshes/collision/asw_hotend_end_effector_shrinked_tip-4mm.stl" scale=".001 .001 .001"/>-->
      <!--</geometry>-->
      <!--<material name="red">-->
        <!--<color rgba="1 0 0 1"/>-->
      <!--</material>-->
    <!--</collision>-->
  <!--</link>-->
  <!--<link name="eef_tcp_frame"/>-->
  <!--&lt;!&ndash; end of link list &ndash;&gt;-->
  <!--&lt;!&ndash; joint list &ndash;&gt;-->
  <!--<joint name="eef_base_to_tcp" type="fixed">-->
    <!--<origin rpy="0.0 1.57079632679 0.0" xyz="0.150539 0.001052 0.119157"/>-->
    <!--<parent link="eef_base_link"/>-->
    <!--<child link="eef_tcp_frame"/>-->
  <!--</joint>-->
  <!-- end of joint list -->

  <!--TODO: linear axis-->
  <link name="linear_axis_base_link">
    <visual>
      <geometry>
        <mesh filename="../meshes/linear_track/visual/ucla_linear_axis_visual_rail.stl" scale=".001 .001 .001"/>
      </geometry>
      <material name="">
        <color rgba="0.772549019608 0.780392156863 0.76862745098 1.0"/>
      </material>
    </visual>
    <collision>
      <geometry>
        <mesh filename="../meshes/linear_track/collision/ucla_linear_axis_collision_rail.stl" scale=".001 .001 .001"/>
      </geometry>
      <material name="">
        <color rgba="0.772549019608 0.780392156863 0.76862745098 1.0"/>
      </material>
    </collision>
  </link>
  <link name="linear_axis_zero"/>
  <link name="linear_axis_carriage">
    <visual>
      <geometry>
        <mesh filename="../meshes/linear_track/visual/ucla_linear_axis_visual_carriage.stl" scale=".001 .001 .001"/>
      </geometry>
      <material name="">
        <color rgba="0.15 0.415 0.165 1.0"/>
      </material>
    </visual>
    <collision>
      <geometry>
        <mesh filename="../meshes/linear_track/collision/ucla_linear_axis_collision_carriage.stl" scale=".001 .001 .001"/>
      </geometry>
      <material name="">
        <color rgba="0.15 0.415 0.165 1.0"/>
      </material>
    </collision>
  </link>
  <link name="linear_axis_robot_mount"/>
  <!--	End of link list-->
  <!-- Joint list -->
  <joint name="linear_axis_joint_1" type="fixed">
    <parent link="linear_axis_base_link"/>
    <child link="linear_axis_zero"/>
    <origin rpy="0 0 0" xyz="-3.153 -0.212 0.470"/>
  </joint>
  <joint name="linear_axis_actuation_joint" type="prismatic">
    <parent link="linear_axis_zero"/>
    <child link="linear_axis_carriage"/>
    <origin rpy="0 0 0" xyz="0 0 0"/>
    <axis xyz="1 0 0"/>
    <limit effort="1" lower="0" upper="5.4" velocity="1"/>
  </joint>
  <joint name="linear_axis_joint_3" type="fixed">
    <parent link="linear_axis_carriage"/>
    <child link="linear_axis_robot_mount"/>
    <origin rpy="0 0 0" xyz="0 0 0.470"/>
  </joint>
  <!-- End of joint list -->

  <!--base_link-->
  <!--Link list-->
  <link name="base_link"/>
  <!--bind the rail to word_frame, can be disabled if using modile platform-->
  <joint name="linear_axis_to_base_link" type="fixed">
    <origin rpy="0 0 1.57079632679" xyz="0 0 0"/>
    <parent link="base_link"/>
    <!--<child link="robot_base_link"/>-->
    <child link="linear_axis_base_link"/>
  </joint>

  <joint name="robot_to_linear_axis" type="fixed">
    <origin rpy="0 0 -1.57079632679" xyz="0 0 0"/>
    <parent link="linear_axis_robot_mount"/>
    <child link="robot_base_link"/>
  </joint>

   <joint name="ee_to_robot" type="fixed">
     <parent link="robot_tool0"/>
     <child link="eef_base_link"/>
     <origin rpy="0 0 0" xyz="0 0 0"/>
   </joint>

  <!-- End of joint list -->
</robot>
