<?xml version="1.0" ?>
<!-- =================================================================================== -->
<!-- |    This document was autogenerated by xacro from eth_rfl_fixed-xz.xacro         | -->
<!-- |    EDITING THIS FILE BY HAND IS NOT RECOMMENDED                                 | -->
<!-- =================================================================================== -->
<robot name="eth_rfl" xmlns:xacro="http://ros.org/wiki/xacro">
  <!-- Conversion were obtained from http://www.e-paint.co.uk/Lab_values.asp
       unless otherwise stated. -->
  <!-- link list -->
    <link name="l_robot_base_link">
    <visual>
      <origin rpy="0 0 0" xyz="0 0 0"/>
      <geometry>
        <mesh filename="../meshes/irb4400l_30_243/visual/base_link.stl"/>
      </geometry>
      <material name="">
        <color rgba="0.7372549 0.3490196 0.1607843 1"/>
      </material>
    </visual>
    <collision>
      <geometry>
        <mesh filename="../meshes/irb4400l_30_243/collision/base_link.stl"/>
      </geometry>
      <material name="">
        <color rgba="1 1 0 1"/>
      </material>
    </collision>
  </link>
  <link name="l_robot_link_1">
    <visual>
      <origin rpy="0 0 0" xyz="0 0 0"/>
      <geometry>
        <mesh filename="../meshes/irb4400l_30_243/visual/link_1.stl"/>
      </geometry>
      <material name="">
        <color rgba="0.7372549 0.3490196 0.1607843 1"/>
      </material>
    </visual>
    <collision>
      <origin rpy="0 0 0" xyz="0 0 0"/>
      <geometry>
        <mesh filename="../meshes/irb4400l_30_243/collision/link_1.stl"/>
      </geometry>
      <material name="">
        <color rgba="1 1 0 1"/>
      </material>
    </collision>
  </link>
  <link name="l_robot_link_2">
    <visual>
      <origin rpy="0 0 0" xyz="0 0 0"/>
      <geometry>
        <mesh filename="../meshes/irb4400l_30_243/visual/link_2.stl"/>
      </geometry>
      <material name="">
        <color rgba="0.7372549 0.3490196 0.1607843 1"/>
      </material>
    </visual>
    <collision>
      <origin rpy="0 0 0" xyz="0 0 0"/>
      <geometry>
        <mesh filename="../meshes/irb4400l_30_243/collision/link_2.stl"/>
      </geometry>
      <material name="">
        <color rgba="1 1 0 1"/>
      </material>
    </collision>
  </link>
  <link name="l_robot_link_3">
    <visual>
      <origin rpy="0 0 0" xyz="0 0 0"/>
      <geometry>
        <mesh filename="../meshes/irb4400l_30_243/visual/link_3.stl"/>
      </geometry>
      <material name="">
        <color rgba="0.7372549 0.3490196 0.1607843 1"/>
      </material>
    </visual>
    <collision>
      <origin rpy="0 0 0" xyz="0 0 0"/>
      <geometry>
        <mesh filename="../meshes/irb4400l_30_243/collision/link_3.stl"/>
      </geometry>
      <material name="">
        <color rgba="1 1 0 1"/>
      </material>
    </collision>
  </link>
  <link name="l_robot_link_4">
    <visual>
      <origin rpy="0 0 0" xyz="0 0 0"/>
      <geometry>
        <mesh filename="../meshes/irb4400l_30_243/visual/link_4.stl"/>
      </geometry>
      <material name="">
        <color rgba="0.7372549 0.3490196 0.1607843 1"/>
      </material>
    </visual>
    <collision>
      <origin rpy="0 0 0" xyz="0 0 0"/>
      <geometry>
        <mesh filename="../meshes/irb4400l_30_243/collision/link_4.stl"/>
      </geometry>
      <material name="">
        <color rgba="1 1 0 1"/>
      </material>
    </collision>
  </link>
  <link name="l_robot_link_5">
    <visual>
      <origin rpy="0 0 0" xyz="0 0 0"/>
      <geometry>
        <mesh filename="../meshes/irb4400l_30_243/visual/link_5.stl"/>
      </geometry>
      <material name="">
        <color rgba="0.7372549 0.3490196 0.1607843 1"/>
      </material>
    </visual>
    <collision>
      <origin rpy="0 0 0" xyz="0 0 0"/>
      <geometry>
        <mesh filename="../meshes/irb4400l_30_243/collision/link_5.stl"/>
      </geometry>
      <material name="">
        <color rgba="1 1 0 1"/>
      </material>
    </collision>
  </link>
  <link name="l_robot_link_6">
    <visual>
      <origin rpy="0 0 0" xyz="0 0 0"/>
      <geometry>
        <mesh filename="../meshes/irb4400l_30_243/visual/link_6.stl"/>
      </geometry>
      <material name="">
        <color rgba="0.1882353 0.1960784 0.2039216 1"/>
      </material>
    </visual>
    <collision>
      <origin rpy="0 0 0" xyz="0 0 0"/>
      <geometry>
        <mesh filename="../meshes/irb4400l_30_243/collision/link_6.stl"/>
      </geometry>
      <material name="">
        <color rgba="1 1 0 1"/>
      </material>
    </collision>
  </link>
  <link name="l_robot_tool0"/>
  <!-- end of link list -->
  <!-- joint list -->
  <joint name="l_robot_joint_1" type="revolute">
    <origin rpy="0 0 0" xyz="0 0 0"/>
    <parent link="l_robot_base_link"/>
    <child link="l_robot_link_1"/>
    <axis xyz="0 0 1"/>
    <limit effort="0" lower="-2.87979" upper="2.87979" velocity="2.618"/>
  </joint>
  <joint name="l_robot_joint_2" type="revolute">
    <origin rpy="0 0 0" xyz="0.2 0 0.68"/>
    <parent link="l_robot_link_1"/>
    <child link="l_robot_link_2"/>
    <axis xyz="0 1 0"/>
    <limit effort="0" lower="-1.2217" upper="1.658" velocity="2.0944"/>
  </joint>
  <joint name="l_robot_joint_3" type="revolute">
    <origin rpy="0 0 0" xyz="0 0 0.89"/>
    <parent link="l_robot_link_2"/>
    <child link="l_robot_link_3"/>
    <axis xyz="0 1 0"/>
    <limit effort="0" lower="-1.0472" upper="1.1345" velocity="2.0944"/>
  </joint>
  <joint name="l_robot_joint_4" type="revolute">
    <origin rpy="0 0 0" xyz="1.38 0 0.15"/>
    <parent link="l_robot_link_3"/>
    <child link="l_robot_link_4"/>
    <axis xyz="1 0 0"/>
    <limit effort="0" lower="-3.49" upper="3.49" velocity="3.927"/>
  </joint>
  <joint name="l_robot_joint_5" type="revolute">
    <origin rpy="0 0 0" xyz="0 0 0"/>
    <parent link="l_robot_link_4"/>
    <child link="l_robot_link_5"/>
    <axis xyz="0 1 0"/>
    <limit effort="0" lower="-2.0944" upper="2.0944" velocity="4.3633"/>
  </joint>
  <joint name="l_robot_joint_6" type="revolute">
    <origin rpy="0 0 0" xyz="0 0 0"/>
    <parent link="l_robot_link_5"/>
    <child link="l_robot_link_6"/>
    <axis xyz="1 0 0"/>
    <limit effort="0" lower="-6.9813" upper="6.9813" velocity="5.7596"/>
  </joint>
  <joint name="l_robot_joint_6-tool0" type="fixed">
    <parent link="l_robot_link_6"/>
    <child link="l_robot_tool0"/>
    <origin rpy="0 0 0" xyz="0.14 0 0"/>
  </joint>
  <!-- end of joint list -->
  <!-- ROS base_link to ABB World Coordinates transform -->
  <link name="l_robot_base"/>
  <joint name="l_robot_base_link-base" type="fixed">
    <origin rpy="0 0 0" xyz="0 0 0"/>
    <parent link="l_robot_base_link"/>
    <child link="l_robot_base"/>
  </joint>

  <!-- link list -->
  <!--
  <link name="r_eef_base_link"/>
  -->

  <link name="l_eef_base_link">
    <visual>
      <origin rpy="0 0 0" xyz="0.0 0.0 0.0"/>
      <geometry>
        <mesh filename="../meshes/eth_rfl_gripper/visual/eth_rfl_gripper_visual.stl" scale=".001 .001 .001"/>
      </geometry>
      <material name="grey">
        <color rgba="0.5 0.5 0.5 1.0"/>
      </material>
    </visual>
    <collision>
      <origin rpy="0 0 0" xyz="0.0 0.0 0.0"/>
      <geometry>
        <mesh filename="../meshes/eth_rfl_gripper/collision/eth_rfl_gripper_collision.stl" scale=".001 .001 .001"/>
      </geometry>
      <material name="red">
        <color rgba="1 0 0 1"/>
      </material>
    </collision>
  </link>

  <link name="l_eef_tcp_frame"/>
  <!-- end of link list -->

  <!-- joint list -->
  <!--
  <joint name="l_eef_base_to_tcp" type="fixed">
    <origin rpy="0 0 0" xyz="0.0 0.0 0"/>
    <parent link="l_eef_base_link"/>
    <child link="l_eef_tcp_frame"/>
  </joint>
  -->
  <joint name="l_eef_base_to_tcp" type="fixed">
    <origin rpy="0 0 0" xyz="0.0 0.0 0.475"/>
    <parent link="l_eef_base_link"/>
    <child link="l_eef_tcp_frame"/>
  </joint>
  <!-- end of joint list -->
  <!--end left robot definition-->

  <!--start of right robot definition-->
  <link name="r_robot_base_link">
    <visual>
      <origin rpy="0 0 0" xyz="0 0 0"/>
      <geometry>
        <mesh filename="../meshes/irb4400l_30_243/visual/base_link.stl"/>
      </geometry>
      <material name="">
        <color rgba="0.7372549 0.3490196 0.1607843 1"/>
      </material>
    </visual>
    <collision>
      <geometry>
        <mesh filename="../meshes/irb4400l_30_243/collision/base_link.stl"/>
      </geometry>
      <material name="">
        <color rgba="1 1 0 1"/>
      </material>
    </collision>
  </link>
  <link name="r_robot_link_1">
    <visual>
      <origin rpy="0 0 0" xyz="0 0 0"/>
      <geometry>
        <mesh filename="../meshes/irb4400l_30_243/visual/link_1.stl"/>
      </geometry>
      <material name="">
        <color rgba="0.7372549 0.3490196 0.1607843 1"/>
      </material>
    </visual>
    <collision>
      <origin rpy="0 0 0" xyz="0 0 0"/>
      <geometry>
        <mesh filename="../meshes/irb4400l_30_243/collision/link_1.stl"/>
      </geometry>
      <material name="">
        <color rgba="1 1 0 1"/>
      </material>
    </collision>
  </link>
  <link name="r_robot_link_2">
    <visual>
      <origin rpy="0 0 0" xyz="0 0 0"/>
      <geometry>
        <mesh filename="../meshes/irb4400l_30_243/visual/link_2.stl"/>
      </geometry>
      <material name="">
        <color rgba="0.7372549 0.3490196 0.1607843 1"/>
      </material>
    </visual>
    <collision>
      <origin rpy="0 0 0" xyz="0 0 0"/>
      <geometry>
        <mesh filename="../meshes/irb4400l_30_243/collision/link_2.stl"/>
      </geometry>
      <material name="">
        <color rgba="1 1 0 1"/>
      </material>
    </collision>
  </link>
  <link name="r_robot_link_3">
    <visual>
      <origin rpy="0 0 0" xyz="0 0 0"/>
      <geometry>
        <mesh filename="../meshes/irb4400l_30_243/visual/link_3.stl"/>
      </geometry>
      <material name="">
        <color rgba="0.7372549 0.3490196 0.1607843 1"/>
      </material>
    </visual>
    <collision>
      <origin rpy="0 0 0" xyz="0 0 0"/>
      <geometry>
        <mesh filename="../meshes/irb4400l_30_243/collision/link_3.stl"/>
      </geometry>
      <material name="">
        <color rgba="1 1 0 1"/>
      </material>
    </collision>
  </link>
  <link name="r_robot_link_4">
    <visual>
      <origin rpy="0 0 0" xyz="0 0 0"/>
      <geometry>
        <mesh filename="../meshes/irb4400l_30_243/visual/link_4.stl"/>
      </geometry>
      <material name="">
        <color rgba="0.7372549 0.3490196 0.1607843 1"/>
      </material>
    </visual>
    <collision>
      <origin rpy="0 0 0" xyz="0 0 0"/>
      <geometry>
        <mesh filename="../meshes/irb4400l_30_243/collision/link_4.stl"/>
      </geometry>
      <material name="">
        <color rgba="1 1 0 1"/>
      </material>
    </collision>
  </link>
  <link name="r_robot_link_5">
    <visual>
      <origin rpy="0 0 0" xyz="0 0 0"/>
      <geometry>
        <mesh filename="../meshes/irb4400l_30_243/visual/link_5.stl"/>
      </geometry>
      <material name="">
        <color rgba="0.7372549 0.3490196 0.1607843 1"/>
      </material>
    </visual>
    <collision>
      <origin rpy="0 0 0" xyz="0 0 0"/>
      <geometry>
        <mesh filename="../meshes/irb4400l_30_243/collision/link_5.stl"/>
      </geometry>
      <material name="">
        <color rgba="1 1 0 1"/>
      </material>
    </collision>
  </link>
  <link name="r_robot_link_6">
    <visual>
      <origin rpy="0 0 0" xyz="0 0 0"/>
      <geometry>
        <mesh filename="../meshes/irb4400l_30_243/visual/link_6.stl"/>
      </geometry>
      <material name="">
        <color rgba="0.1882353 0.1960784 0.2039216 1"/>
      </material>
    </visual>
    <collision>
      <origin rpy="0 0 0" xyz="0 0 0"/>
      <geometry>
        <mesh filename="../meshes/irb4400l_30_243/collision/link_6.stl"/>
      </geometry>
      <material name="">
        <color rgba="1 1 0 1"/>
      </material>
    </collision>
  </link>
  <link name="r_robot_tool0"/>
  <!-- end of link list -->
  <!-- joint list -->
  <joint name="r_robot_joint_1" type="revolute">
    <origin rpy="0 0 0" xyz="0 0 0"/>
    <parent link="r_robot_base_link"/>
    <child link="r_robot_link_1"/>
    <axis xyz="0 0 1"/>
    <limit effort="0" lower="-2.87979" upper="2.87979" velocity="2.618"/>
  </joint>
  <joint name="r_robot_joint_2" type="revolute">
    <origin rpy="0 0 0" xyz="0.2 0 0.68"/>
    <parent link="r_robot_link_1"/>
    <child link="r_robot_link_2"/>
    <axis xyz="0 1 0"/>
    <limit effort="0" lower="-1.2217" upper="1.658" velocity="2.0944"/>
  </joint>
  <joint name="r_robot_joint_3" type="revolute">
    <origin rpy="0 0 0" xyz="0 0 0.89"/>
    <parent link="r_robot_link_2"/>
    <child link="r_robot_link_3"/>
    <axis xyz="0 1 0"/>
    <limit effort="0" lower="-1.0472" upper="1.1345" velocity="2.0944"/>
  </joint>
  <joint name="r_robot_joint_4" type="revolute">
    <origin rpy="0 0 0" xyz="1.38 0 0.15"/>
    <parent link="r_robot_link_3"/>
    <child link="r_robot_link_4"/>
    <axis xyz="1 0 0"/>
    <limit effort="0" lower="-3.49" upper="3.49" velocity="3.927"/>
  </joint>
  <joint name="r_robot_joint_5" type="revolute">
    <origin rpy="0 0 0" xyz="0 0 0"/>
    <parent link="r_robot_link_4"/>
    <child link="r_robot_link_5"/>
    <axis xyz="0 1 0"/>
    <limit effort="0" lower="-2.0944" upper="2.0944" velocity="4.3633"/>
  </joint>
  <joint name="r_robot_joint_6" type="revolute">
    <origin rpy="0 0 0" xyz="0 0 0"/>
    <parent link="r_robot_link_5"/>
    <child link="r_robot_link_6"/>
    <axis xyz="1 0 0"/>
    <limit effort="0" lower="-6.9813" upper="6.9813" velocity="5.7596"/>
  </joint>
  <joint name="r_robot_joint_6-tool0" type="fixed">
    <parent link="r_robot_link_6"/>
    <child link="r_robot_tool0"/>
    <origin rpy="0 0 0" xyz="0.14 0 0"/>
  </joint>
  <!-- end of joint list -->
  <!-- ROS base_link to ABB World Coordinates transform -->
  <link name="r_robot_base"/>
  <joint name="r_robot_base_link-base" type="fixed">
    <origin rpy="0 0 0" xyz="0 0 0"/>
    <parent link="r_robot_base_link"/>
    <child link="r_robot_base"/>
  </joint>
  <!-- link list -->
  <!--
  <link name="r_eef_base_link"/>
  -->

  <link name="r_eef_base_link">
    <visual>
      <origin rpy="0 0 0" xyz="0.0 0.0 0.0"/>
      <geometry>
        <mesh filename="../meshes/eth_rfl_gripper/visual/eth_rfl_gripper_visual.stl" scale=".001 .001 .001"/>
      </geometry>
      <material name="grey">
        <color rgba="0.5 0.5 0.5 1.0"/>
      </material>
    </visual>
    <collision>
      <origin rpy="0 0 0" xyz="0.0 0.0 0.0"/>
      <geometry>
        <mesh filename="../meshes/eth_rfl_gripper/collision/eth_rfl_gripper_collision.stl" scale=".001 .001 .001"/>
      </geometry>
      <material name="red">
        <color rgba="1 0 0 1"/>
      </material>
    </collision>
  </link>

  <link name="r_eef_tcp_frame"/>
  <!-- end of link list -->

  <!-- joint list -->
  <!--
  <joint name="r_eef_base_to_tcp" type="fixed">
    <origin rpy="0 0 0" xyz="0.0 0.0 0"/>
    <parent link="r_eef_base_link"/>
    <child link="r_eef_tcp_frame"/>
  </joint>
  -->
  <joint name="r_eef_base_to_tcp" type="fixed">
    <origin rpy="0 0 0" xyz="0.0 0.0 0.475"/>
    <parent link="r_eef_base_link"/>
    <child link="r_eef_tcp_frame"/>
  </joint>
  <!-- end of joint list -->
  <!--end of right robot configuration-->

  <!--	Link list-->
  <link name="gantry_base_link">
    <visual>
      <geometry>
        <mesh filename="../meshes/eth_rfl_track/visual/eth_gudel_track_x_rail_visual.stl" scale=".001 .001 .001"/>
      </geometry>
      <material name="">
        <color rgba="0.772549019608 0.780392156863 0.76862745098 1.0"/>
      </material>
    </visual>
    <collision>
      <geometry>
        <mesh filename="../meshes/eth_rfl_track/collision/eth_gudel_track_x_rail_collision.stl" scale=".001 .001 .001"/>
      </geometry>
      <material name="">
        <color rgba="0.772549019608 0.780392156863 0.76862745098 1.0"/>
      </material>
    </collision>
  </link>
  <link name="gantry_y_bridge">
    <visual>
      <geometry>
        <mesh filename="../meshes/eth_rfl_track/visual/eth_gudel_track_y_bridge_visual.stl" scale=".001 .001 .001"/>
      </geometry>
      <material name="">
        <color rgba="0.15 0.415 0.165 1.0"/>
      </material>
    </visual>
    <collision>
      <geometry>
        <mesh filename="../meshes/eth_rfl_track/collision/eth_gudel_track_y_bridge_collision.stl" scale=".001 .001 .001"/>
      </geometry>
      <material name="">
        <color rgba="0.15 0.415 0.165 1.0"/>
      </material>
    </collision>
  </link>

  <link name="l_gantry_xy_carriage">
    <visual>
      <geometry>
        <mesh filename="../meshes/eth_rfl_track/visual/eth_gudel_track_xy_carriage_visual.stl" scale=".001 .001 .001"/>
      </geometry>
      <material name="">
        <color rgba="0.15 0.415 0.165 1.0"/>
      </material>
    </visual>
    <collision>
      <geometry>
        <mesh filename="../meshes/eth_rfl_track/collision/eth_gudel_track_xy_carriage_collision.stl" scale=".001 .001 .001"/>
      </geometry>
      <material name="">
        <color rgba="0.15 0.415 0.165 1.0"/>
      </material>
    </collision>
  </link>
  <link name="r_gantry_xy_carriage">
    <visual>
      <geometry>
        <mesh filename="../meshes/eth_rfl_track/visual/eth_gudel_track_xy_carriage_visual.stl" scale=".001 .001 .001"/>
      </geometry>
      <material name="">
        <color rgba="0.15 0.415 0.165 1.0"/>
      </material>
    </visual>
    <collision>
      <geometry>
        <mesh filename="../meshes/eth_rfl_track/collision/eth_gudel_track_xy_carriage_collision.stl" scale=".001 .001 .001"/>
      </geometry>
      <material name="">
        <color rgba="0.15 0.415 0.165 1.0"/>
      </material>
    </collision>
  </link>

   <link name="l_gantry_z_carriage">
    <visual>
      <geometry>
        <mesh filename="../meshes/eth_rfl_track/visual/eth_gudel_track_z_carriage_visual.stl" scale=".001 .001 .001"/>
      </geometry>
      <material name="">
        <color rgba="0.772549019608 0.780392156863 0.76862745098 1.0"/>
      </material>
    </visual>
    <collision>
      <geometry>
        <mesh filename="../meshes/eth_rfl_track/collision/eth_gudel_track_z_carriage_collision.stl" scale=".001 .001 .001"/>
      </geometry>
      <material name="">
        <color rgba="0.772549019608 0.780392156863 0.76862745098 1.0"/>
      </material>
    </collision>
  </link>
  <link name="r_gantry_z_carriage">
    <visual>
      <geometry>
        <mesh filename="../meshes/eth_rfl_track/visual/eth_gudel_track_z_carriage_visual.stl" scale=".001 .001 .001"/>
      </geometry>
      <material name="">
        <color rgba="0.772549019608 0.780392156863 0.76862745098 1.0"/>
      </material>
    </visual>
    <collision>
      <geometry>
        <mesh filename="../meshes/eth_rfl_track/collision/eth_gudel_track_z_carriage_collision.stl" scale=".001 .001 .001"/>
      </geometry>
      <material name="">
        <color rgba="0.772549019608 0.780392156863 0.76862745098 1.0"/>
      </material>
    </collision>
  </link>

  <link name="l_gantry_robot_mount"/>
  <link name="r_gantry_robot_mount"/>
  <!--	End of link list-->

  <!-- Joint list -->
  <joint name="gantry_x_joint" type="prismatic">
    <parent link="gantry_base_link"/>
    <child link="gantry_y_bridge"/>
    <origin rpy="0 0 0" xyz="0 0 0"/>
    <axis xyz="1 0 0"/>
    <limit effort="1" lower="0" upper="20" velocity="1.5"/>
  </joint>

   <joint name="l_gantry_y_joint" type="prismatic">
    <parent link="gantry_y_bridge"/>
    <child link="l_gantry_xy_carriage"/>
    <origin rpy="0 0 0" xyz="0 12.673 0"/>
    <axis xyz="0 -1 0"/>
    <limit effort="1" lower="0" upper="12.673" velocity="1.5"/>
  </joint>
  <joint name="r_gantry_y_joint" type="prismatic">
    <parent link="gantry_y_bridge"/>
    <child link="r_gantry_xy_carriage"/>
    <origin rpy="0 0 0" xyz="0 0 0"/>
    <axis xyz="0 1 0"/>
    <limit effort="1" lower="0" upper="12.673" velocity="1.5"/>
  </joint>

  <joint name="l_gantry_z_joint" type="prismatic">
    <parent link="l_gantry_xy_carriage"/>
    <child link="l_gantry_z_carriage"/>
    <origin rpy="0 0 0" xyz="0 0 0"/>
    <axis xyz="0 0 -1"/>
    <limit effort="1" lower="0" upper="1.227" velocity="1"/>
  </joint>
  <joint name="r_gantry_z_joint" type="prismatic">
    <parent link="r_gantry_xy_carriage"/>
    <child link="r_gantry_z_carriage"/>
    <origin rpy="0 0 0" xyz="0 0 0"/>
    <axis xyz="0 0 -1"/>
    <limit effort="1" lower="0" upper="1.227" velocity="1"/>
  </joint>

  <joint name="l_gantry_z_carriage_mount" type="fixed">
    <parent link="l_gantry_z_carriage"/>
    <child link="l_gantry_robot_mount"/>
    <origin rpy="0 3.14159265359 0" xyz="0.545 -0.0075 -1.2"/>
  </joint>
  <joint name="r_gantry_z_carriage_mount" type="fixed">
    <parent link="r_gantry_z_carriage"/>
    <child link="r_gantry_robot_mount"/>
    <origin rpy="0 3.14159265359 0" xyz="0.545 -0.0075 -1.2"/>
  </joint>
  <!-- End of joint list -->

  <link name="workspace_base_link"/>
  <link name="workspace_objects">
    <visual>
      <geometry>
        <mesh filename="../meshes/eth_rfl_workspace/collision/robarch_2018_workspace_collision.stl" scale=".001 .001 .001"/>
      </geometry>
      <material name="">
        <color rgba="0.909803921569 0.81568627451 0.662745098039 1.0"/>
      </material>
    </visual>
    <collision>
      <geometry>
        <mesh filename="../meshes/eth_rfl_workspace/collision/robarch_2018_workspace_collision.stl" scale=".001 .001 .001"/>
      </geometry>
    </collision>
  </link>
  <joint name="workspace_baselink_to_objects" type="fixed">
    <parent link="workspace_base_link"/>
    <child link="workspace_objects"/>
    <origin rpy="0 0 0" xyz="0 0 0"/>
  </joint>

  <!-- Link list -->
  <link name="base_link"/>
  <!-- End of link list -->

  <!-- Joint list -->
  <joint name="gantry_to_base_link" type="fixed">
    <origin rpy="0 0 0" xyz="1.550 0.8675 5.7766"/>
    <parent link="base_link"/>
    <child link="gantry_base_link"/>
  </joint>

  <joint name="l_robot_to_gantry" type="fixed">
    <origin rpy="0 0 0" xyz="0 0 0"/>
    <parent link="l_gantry_robot_mount"/>
    <child link="l_robot_base_link"/>
  </joint>
  <joint name="r_robot_to_gantry" type="fixed">
    <origin rpy="0 0 0" xyz="0 0 0"/>
    <parent link="r_gantry_robot_mount"/>
    <child link="r_robot_base_link"/>
  </joint>

  <joint name="l_ee_to_l_robot" type="fixed">
    <parent link="l_robot_tool0"/>
    <child link="l_eef_base_link"/>
    <origin rpy="0 1.57079632679 0" xyz="0 0 0"/>
  </joint>
  <joint name="r_ee_to_r_robot" type="fixed">
    <parent link="r_robot_tool0"/>
    <child link="r_eef_base_link"/>
    <origin rpy="0 1.57079632679 0" xyz="0 0 0"/>
  </joint>

  <joint name="world_to_workspace" type="fixed">
    <parent link="base_link"/>
    <child link="workspace_base_link"/>
    <origin rpy="0 0 0" xyz="0 0 0"/>
  </joint>

  <!-- End of joint list -->
</robot>
